<?xml version="1.0"?>
<robot name="hydraulic_arm">

  <material name="blue"><color rgba="0 0.4 0.8 1"/></material> <material name="orange"><color rgba="1 0.5 0 1"/></material> <material name="gray"><color rgba="0.2 0.2 0.2 1"/></material>

  <link name="base_link">
    <visual>
      <origin xyz="0 0 0.25" rpy="0 0 0"/>
      <geometry><cylinder radius="0.05" length="0.5"/></geometry>
      <material name="gray"><color rgba="0.2 0.2 0.2 1"/></material>
    </visual>
  </link>

  <joint name="joint1" type="revolute">
    <parent link="base_link"/>
    <child link="link1"/>
    <origin xyz="0 0 0.5" rpy="0 0 0"/>
    <axis xyz="0 0 1"/> <limit lower="-1.047" upper="1.047" effort="100" velocity="1.0"/>
  </joint>

  <link name="link1">
    <visual>
      <origin xyz="0.095 0 0" rpy="0 1.5708 0"/> 
      <geometry><cylinder radius="0.04" length="0.19"/></geometry>
      <material name="blue"><color rgba="0 0.4 0.8 1"/></material>
    </visual>
  </link>

  <joint name="joint2" type="revolute">
    <parent link="link1"/>
    <child link="link2"/>
    <origin xyz="0.19 0 0" rpy="1.5708 0 0"/> <axis xyz="0 0 1"/> <limit lower="-0.48" upper="1.57" effort="100" velocity="1.0"/>
  </joint>

  <link name="link2">
    <visual>
      <origin xyz="0.045 0 0" rpy="0 1.5708 0"/>
      <geometry><cylinder radius="0.04" length="0.09"/></geometry>
      <material name="blue"><color rgba="0 0.4 0.8 1"/></material>
    </visual>
  </link>

  <joint name="joint3" type="revolute">
    <parent link="link2"/>
    <child link="link3"/>
    <origin xyz="0.09 0 0" rpy="0 0 0"/>
    <axis xyz="0 0 1"/>
    <limit lower="-2.65" upper="-0.73" effort="100" velocity="1.0"/>
  </joint>

  <link name="link3">
    <visual>
      <origin xyz="0.3025 0 0" rpy="0 1.5708 0"/>
      <geometry><cylinder radius="0.035" length="0.605"/></geometry>
      <material name="blue"><color rgba="0 0.4 0.8 1"/></material>
    </visual>
  </link>
  
  <joint name="joint4" type="revolute">
    <parent link="link3"/>
    <child link="link4"/>
    <origin xyz="0.605 0 0" rpy="0 0 0"/>
    <axis xyz="0 0 1"/>
    <limit lower="-1.57" upper="1.57" effort="100" velocity="1.0"/>
  </joint>

  <link name="link4">
    <visual>
      <origin xyz="0.145 0 0" rpy="0 1.5708 0"/>
      <geometry><cylinder radius="0.03" length="0.29"/></geometry>
      <material name="blue"><color rgba="0 0.4 0.8 1"/></material>
    </visual>
  </link>

  
  <joint name="soft_joint_0" type="revolute">
    <parent link="link4"/>
    <child link="soft_0"/>
    <origin xyz="0.29 0 0" rpy="0 0 0"/>
    <axis xyz="0 1 0"/> <limit lower="-0.2" upper="0.2" effort="10" velocity="1.0"/>
  </joint>

  <link name="soft_0">
    <visual>
      <origin xyz="0.0125 0 0" rpy="0 1.5708 0"/>
      <geometry><cylinder radius="0.025" length="0.025"/></geometry>
      <material name="orange"><color rgba="1 0.5 0 1"/></material>
    </visual>
  </link>
        
  <joint name="soft_joint_1" type="revolute">
    <parent link="soft_0"/>
    <child link="soft_1"/>
    <origin xyz="0.025 0 0" rpy="0 0 0"/>
    <axis xyz="0 1 0"/> <limit lower="-0.2" upper="0.2" effort="10" velocity="1.0"/>
  </joint>

  <link name="soft_1">
    <visual>
      <origin xyz="0.0125 0 0" rpy="0 1.5708 0"/>
      <geometry><cylinder radius="0.025" length="0.025"/></geometry>
      <material name="orange"><color rgba="1 0.5 0 1"/></material>
    </visual>
  </link>
        
  <joint name="soft_joint_2" type="revolute">
    <parent link="soft_1"/>
    <child link="soft_2"/>
    <origin xyz="0.025 0 0" rpy="0 0 0"/>
    <axis xyz="0 1 0"/> <limit lower="-0.2" upper="0.2" effort="10" velocity="1.0"/>
  </joint>

  <link name="soft_2">
    <visual>
      <origin xyz="0.0125 0 0" rpy="0 1.5708 0"/>
      <geometry><cylinder radius="0.025" length="0.025"/></geometry>
      <material name="orange"><color rgba="1 0.5 0 1"/></material>
    </visual>
  </link>
        
  <joint name="soft_joint_3" type="revolute">
    <parent link="soft_2"/>
    <child link="soft_3"/>
    <origin xyz="0.025 0 0" rpy="0 0 0"/>
    <axis xyz="0 1 0"/> <limit lower="-0.2" upper="0.2" effort="10" velocity="1.0"/>
  </joint>

  <link name="soft_3">
    <visual>
      <origin xyz="0.0125 0 0" rpy="0 1.5708 0"/>
      <geometry><cylinder radius="0.025" length="0.025"/></geometry>
      <material name="orange"><color rgba="1 0.5 0 1"/></material>
    </visual>
  </link>
        
  <joint name="soft_joint_4" type="revolute">
    <parent link="soft_3"/>
    <child link="soft_4"/>
    <origin xyz="0.025 0 0" rpy="0 0 0"/>
    <axis xyz="0 1 0"/> <limit lower="-0.2" upper="0.2" effort="10" velocity="1.0"/>
  </joint>

  <link name="soft_4">
    <visual>
      <origin xyz="0.0125 0 0" rpy="0 1.5708 0"/>
      <geometry><cylinder radius="0.025" length="0.025"/></geometry>
      <material name="orange"><color rgba="1 0.5 0 1"/></material>
    </visual>
  </link>
        
  <joint name="soft_joint_5" type="revolute">
    <parent link="soft_4"/>
    <child link="soft_5"/>
    <origin xyz="0.025 0 0" rpy="0 0 0"/>
    <axis xyz="0 1 0"/> <limit lower="-0.2" upper="0.2" effort="10" velocity="1.0"/>
  </joint>

  <link name="soft_5">
    <visual>
      <origin xyz="0.0125 0 0" rpy="0 1.5708 0"/>
      <geometry><cylinder radius="0.025" length="0.025"/></geometry>
      <material name="orange"><color rgba="1 0.5 0 1"/></material>
    </visual>
  </link>
        
  <joint name="soft_joint_6" type="revolute">
    <parent link="soft_5"/>
    <child link="soft_6"/>
    <origin xyz="0.025 0 0" rpy="0 0 0"/>
    <axis xyz="0 1 0"/> <limit lower="-0.2" upper="0.2" effort="10" velocity="1.0"/>
  </joint>

  <link name="soft_6">
    <visual>
      <origin xyz="0.0125 0 0" rpy="0 1.5708 0"/>
      <geometry><cylinder radius="0.025" length="0.025"/></geometry>
      <material name="orange"><color rgba="1 0.5 0 1"/></material>
    </visual>
  </link>
        
  <joint name="soft_joint_7" type="revolute">
    <parent link="soft_6"/>
    <child link="soft_7"/>
    <origin xyz="0.025 0 0" rpy="0 0 0"/>
    <axis xyz="0 1 0"/> <limit lower="-0.2" upper="0.2" effort="10" velocity="1.0"/>
  </joint>

  <link name="soft_7">
    <visual>
      <origin xyz="0.0125 0 0" rpy="0 1.5708 0"/>
      <geometry><cylinder radius="0.025" length="0.025"/></geometry>
      <material name="orange"><color rgba="1 0.5 0 1"/></material>
    </visual>
  </link>
        
  <joint name="soft_joint_8" type="revolute">
    <parent link="soft_7"/>
    <child link="soft_8"/>
    <origin xyz="0.025 0 0" rpy="0 0 0"/>
    <axis xyz="0 1 0"/> <limit lower="-0.2" upper="0.2" effort="10" velocity="1.0"/>
  </joint>

  <link name="soft_8">
    <visual>
      <origin xyz="0.0125 0 0" rpy="0 1.5708 0"/>
      <geometry><cylinder radius="0.025" length="0.025"/></geometry>
      <material name="orange"><color rgba="1 0.5 0 1"/></material>
    </visual>
  </link>
        
  <joint name="soft_joint_9" type="revolute">
    <parent link="soft_8"/>
    <child link="soft_9"/>
    <origin xyz="0.025 0 0" rpy="0 0 0"/>
    <axis xyz="0 1 0"/> <limit lower="-0.2" upper="0.2" effort="10" velocity="1.0"/>
  </joint>

  <link name="soft_9">
    <visual>
      <origin xyz="0.0125 0 0" rpy="0 1.5708 0"/>
      <geometry><cylinder radius="0.025" length="0.025"/></geometry>
      <material name="orange"><color rgba="1 0.5 0 1"/></material>
    </visual>
  </link>
        
</robot>